Workbook

Sheet weights
A1: layer | B1: prin.eigenvector | C1: norm
A2: mean.tas | B2: -0.3979196 | C2: 0.17465097
A3: SD.tas | B3: -0.1728996 | C3: 0.07588739
A4: ES.tas | B4: -0.6169402 | C4: 0.27078135
A5: mean.pr | B5: -0.3250214 | C5: 0.14265521
A6: SD.pr | B6: -0.2554212 | C6: 0.11210698
A7: ES.pr | B7: -0.5101683 | C7: 0.22391811
A9: richness | C9: 0.09068
A10: relative abundance | C10: 0.90932
A12: layer | B12: prin.eigenvector | C12: norm
A13: climate | B13: -0.2448442 | C13: 0.15109571
A14: birds | B14: -0.9028373 | C14: 0.5571495
A15: size | B15: -0.3175589 | C15: 0.19596861
A16: slr | B16: -0.1552175 | C16: 0.09578618
A18: pw to uprotect

Sheet estuary_data
A1: EST_ID | B1: mean.pr | C1: SD.pr | D1: ES0.99.pr | E1: mean.tas | F1: SD.tas | G1: ES0.99.tas | H1: mean.pr.abs | I1: SD.pr.abs | J1: ES0.99.pr.abs | K1: mean.tas.abs | L1: SD.tas.abs | M1: ES0.99.tas.abs | N1: relative.abundance | O1: richness | P1: risk1 | Q1: Area_Ha | R1: mean.pr.abs.norm | S1: SD.pr.abs.norm | T1: ES0.99.pr.abs.norm | U1: mean.tas.abs.norm | V1: SD.tas.abs.norm | W1: ES0.99.tas.abs.norm | X1: relative.abundance.norm | Y1: richness.norm | Z1: risk1.norm | AA1: Area_Ha.norm
A2: 1 | B2: 12.339923 | C2: -7.2039924 | D2: -3.0088099 | E2: 26.564123 | F2: 8.1453764 | G2: 12.683558 | H2: 12.339923 | I2: 7.2039924 | J2: 3.0088099 | K2: 26.564123 | L2: 8.1453764 | M2: 12.683558 | N2: 0.16448572 | O2: 45.070847 | P2: 0 | Q2: 91.553166 | R2: 0.45893808 | S2: 0.29212337 | T2: 0.15405626 | U2: 0.20739514 | V2: 0.39801088 | W2: 0.28978631 | X2: 0.22767974 | Y2: 0.57164578 | Z2: 0 | AA2: 0.0021147564
A3: 2 | B3: 14.675884 | C3: -5.4740313 | D3: -0.94264967 | E3: 27.189767 | F3: 9.2464199 | G3: 13.565362 | H3: 14.675884 | I3: 5.4740313 | J3: 0.94264967 | K3: 27.189767 | L3: 9.2464199 | M3: 13.565362 | N3: 0.25358131 | O3: 55.09095 | P3: 0 | Q3: 122.52264 | R3: 0.54718519 | S3: 0.22180811 | T3: 0.048102423 | U3: 0.2252495 | V3: 0.45216192 | W3: 0.33833068 | X3: 0.35395254 | Y3: 0.7016136 | Z3: 0 | AA3: 0.0028305776
A4: 3 | B4: 15.537479 | C4: 2.6270207 | D4: 5.3607549 | E4: 34.789013 | F4: 11.181107 | G4: 19.262488 | H4: 15.537479 | I4: 2.6270207 | J4: 5.3607549 | K4: 34.789013 | L4: 11.181107 | M4: 19.262488 | N4: 0.10122779 | O4: 38.967194 | P4: 93.995762 | Q4: 97.451312 | R4: 0.57973424 | S4: 0.10608971 | T4: 0.2746653 | U4: 0.4421138 | V4: 0.54731286 | W4: 0.6519643 | X4: 0.13802596 | Y4: 0.49247709 | Z4: 0.080513603 | AA4: 0.0022510847
A5: 4 | B5: 15.4204 | C5: 3.8434654 | D5: 6.2212854 | E5: 34.836784 | F5: 10.141271 | G5: 18.266693 | H5: 15.4204 | I5: 3.8434654 | J5: 6.2212854 | K5: 34.836784 | L5: 10.141271 | M5: 18.266693 | N5: 0.088183157 | O5: 37.855122 | P5: 16.703968 | Q5: 113.93918 | R5: 0.57531125 | S5: 0.15553281 | T5: 0.31879378 | U5: 0.44347707 | V5: 0.49617209 | W5: 0.59714458 | X5: 0.11953815 | Y5: 0.47805273 | Z5: 0.014308056 | AA5: 0.0026321814
A6: 5 | B6: 14.176214 | C6: -6.0666253 | D6: -1.602347 | E6: 26.763632 | F6: 8.5951754 | G6: 12.89974 | H6: 14.176214 | I6: 6.0666253 | J6: 1.602347 | K6: 26.763632 | L6: 8.5951754 | M6: 12.89974 | N6: 0.14488719 | O6: 40.234993 | P6: 0 | Q6: 115.35458 | R6: 0.52830883 | S6: 0.24589443 | T6: 0.081932069 | U6: 0.21308863 | V6: 0.42013269 | W6: 0.30168735 | X6: 0.19990327 | Y6: 0.50892135 | Z6: 0 | AA6: 0.0026648967
A7: 6 | B7: 13.357268 | C7: -7.173734 | D7: -2.7381504 | E7: 26.605239 | F7: 7.6589236 | G7: 12.635556 | H7: 13.357268 | I7: 7.173734 | J7: 2.7381504 | K7: 26.605239 | L7: 7.6589236 | M7: 12.635556 | N7: 0.27217793 | O7: 70.239601 | P7: 0 | Q7: 176.06916 | R7: 0.49737096 | S7: 0.2908935 | T7: 0.14017669 | U7: 0.20856849 | V7: 0.37408637 | W7: 0.28714372 | X7: 0.38030904 | Y7: 0.8981023 | Z7: 0 | AA7: 0.0040682394
A8: 7 | B8: 19.1832 | C8: 1.4486317 | D8: 9.1220792 | E8: 29.107361 | F8: 5.1238738 | G8: 11.41664 | H8: 19.1832 | I8: 1.4486317 | J8: 9.1220792 | K8: 29.107361 | L8: 5.1238738 | M8: 11.41664 | N8: 0.069557965 | O8: 22.783026 | P8: 258.87381 | Q8: 17.807913 | R8: 0.717461 | S8: 0.058193413 | T8: 0.46754809 | U8: 0.27997307 | V8: 0.24940866 | W8: 0.22004093 | X8: 0.093141158 | Y8: 0.28255701 | Z8: 0.22174258 | AA8: 0.00041022581
A9: 8 | B9: 19.204793 | C9: 1.3463312 | D9: 3.5821255 | E9: 29.039026 | F9: 5.2898816 | G9: 11.092015 | H9: 19.204793 | I9: 1.3463312 | J9: 3.5821255 | K9: 29.039026 | L9: 5.2898816 | M9: 11.092015 | N9: 0.074163027 | O9: 25.588654 | P9: 129.4369 | Q9: 48.64952 | R9: 0.71827673 | S9: 0.054035353 | T9: 0.1834562 | U9: 0.27802294 | V9: 0.25757318 | W9: 0.20216992 | X9: 0.09966779 | Y9: 0.31894798 | Z9: 0.11087129 | AA9: 0.0011230915
A10: 9 | B10: 16.753121 | C10: -2.8123976 | D10: 1.5088968 | E10: 30.226824 | F10: 10.006258 | G10: 15.331612 | H10: 16.753121 | I10: 2.8123976 | J10: 1.5088968 | K10: 30.226824 | L10: 10.006258 | M10: 15.331612 | N10: 0.17148851 | O10: 55.609222 | P10: 0 | Q10: 148.57937 | R10: 0.62565834 | S10: 0.11362447 | T10: 0.077139889 | U10: 0.31191984 | V10: 0.48953192 | W10: 0.43556486 | X10: 0.2376046 | Y10: 0.70833596 | Z10: 0 | AA10: 0.0034328467
A11: 10 | B11: 15.357637 | C11: -4.2837842 | D11: 0.064974888 | E11: 27.73599 | F11: 9.0115603 | G11: 13.866429 | H11: 15.357637 | I11: 4.2837842 | J11: 0.064974888 | K11: 27.73599 | L11: 9.0115603 | M11: 13.866429 | N11: 0.13323337 | O11: 38.116631 | P11: 1.1345328 | Q11: 118.31326 | R11: 0.57294021 | S11: 0.17342983 | T11: 0.0030947753 | U11: 0.2408374 | V11: 0.44061116 | W11: 0.35490475 | X11: 0.18338661 | Y11: 0.48144469 | Z11: 0.00097180258 | AA11: 0.002733283
A12: 11 | B12: 12.345041 | C12: -7.0921979 | D12: -2.9128168 | E12: 26.606877 | F12: 8.2573802 | G12: 12.766241 | H12: 12.345041 | I12: 7.0921979 | J12: 2.9128168 | K12: 26.606877 | L12: 8.2573802 | M12: 12.766241 | N12: 0.16163768 | O12: 44.607254 | P12: 0 | Q12: 288.65926 | R12: 0.45913142 | S12: 0.28757942 | T12: 0.14913368 | U12: 0.20861524 | V12: 0.4035194 | W12: 0.2943381 | X12: 0.22364328 | Y12: 0.56563266 | Z12: 0 | AA12: 0.0066706205
A13: 12 | B13: 11.036824 | C13: -6.9312731 | D13: -3.2879928 | E13: 33.032475 | F13: 15.625643 | G13: 21.719809 | H13: 11.036824 | I13: 6.9312731 | J13: 3.2879928 | K13: 33.032475 | L13: 15.625643 | M13: 21.719809 | N13: 0.195241 | O13: 57.849735 | P13: 540.43646 | Q13: 17.887168 | R13: 0.40971007 | S13: 0.28103854 | T13: 0.16837291 | U13: 0.39198641 | V13: 0.76590209 | W13: 0.78724277 | X13: 0.27126838 | Y13: 0.73739699 | Z13: 0.46291967 | AA13: 0.00041205771
... A151: 150 | B151: 19.020738 | C151: -1.7111851 | D151: 3.6150133 | E151: 29.7046 | F151: 8.9184902 | G151: 12.061957 | H151: 19.020738 | I151: 1.7111851 | J151: 3.6150133 | K151: 29.7046 | L151: 8.9184902 | M151: 12.061957 | N151: 0.076713875 | O151: 34.567738 | P151: 209.98678 | Q151: 80.574508 | R151: 0.71132357 | S151: 0.068865051 | T151: 0.1851427 | U151: 0.29701683 | V151: 0.43603382 | W151: 0.25556643 | X151: 0.10328304 | Y151: 0.43541304 | Z151: 0.1798676 | AA151: 0.0018609982
A152: 151 | B152: 18.139428 | C152: 2.5089416 | D152: 12.766021 | E152: 31.812911 | F152: 9.228498 | G152: 17.743024 | H152: 18.139428 | I152: 2.5089416 | J152: 12.766021 | K152: 31.812911 | L152: 9.228498 | M152: 17.743024 | N152: NA | O152: 39 | P152: 591.71156 | Q152: 11.298618 | R152: 0.67802975 | S152: 0.10129032 | T152: 0.65441142 | U152: 0.35718296 | V152: 0.45128049 | W152: 0.56831598 | X152: NA | Y152: 0.49290262 | Z152: 0.50684019 | AA152: 0.00025977149
A153: 152 | B153: 15.146458 | C153: -4.9536854 | D153: -0.21780152 | E153: 30.193314 | F153: 13.249955 | G153: 18.665164 | H153: 15.146458 | I153: 4.9536854 | J153: 0.21780152 | K153: 30.193314 | L153: 13.249955 | M153: 18.665164 | N153: 0.082917541 | O153: 27.676256 | P153: 427.38486 | Q153: 5.2639245 | R153: 0.56496236 | S153: 0.20065835 | T153: 0.010931809 | U153: 0.31096357 | V153: 0.64906202 | W153: 0.61908091 | X153: 0.11207533 | Y153: 0.34602566 | Z153: 0.36608347 | AA153: 0.00012028699
A154: 153 | B154: 15.568751 | C154: -7.1062352 | D154: 0.31219367 | E154: 35.34028 | F154: 6.4155477 | G154: 12.086331 | H154: 15.568751 | I154: 7.1062352 | J154: 0.31219367 | K154: 35.34028 | L154: 6.4155477 | M154: 12.086331 | N154: 0.066851526 | O154: 33.356602 | P154: 128.09222 | Q154: 126.61741 | R154: 0.5809156 | S154: 0.28814998 | T154: 0.015772291 | U154: 0.45784564 | V154: 0.3129352 | W154: 0.25690821 | X154: 0.089305394 | Y154: 0.41970376 | Z154: 0.10971948 | AA154: 0.0029252231
A155: 154 | B155: 15.788913 | C155: -6.7959738 | D155: 0.21373596 | E155: 34.773823 | F155: 6.1318019 | G155: 12.070276 | H155: 15.788913 | I155: 6.7959738 | J155: 0.21373596 | K155: 34.773823 | L155: 6.1318019 | M155: 12.070276 | N155: 0.085957132 | O155: 42.164825 | P155: 192.13834 | Q155: 68.98148 | R155: 0.58923282 | S155: 0.27553922 | T155: 0.010723325 | U155: 0.44168032 | V155: 0.29898014 | W155: 0.25602436 | X155: 0.11638326 | Y155: 0.53395264 | Z155: 0.16457923 | AA155: 0.0015930397
A156: 155 | B156: 15.81902 | C156: -6.3755366 | D156: 0.34084928 | E156: 34.547344 | F156: 6.6351627 | G156: 12.307646 | H156: 15.81902 | I156: 6.3755366 | J156: 0.34084928 | K156: 34.547344 | L156: 6.6351627 | M156: 12.307646 | N156: 0.055785879 | O156: 27.669022 | P156: 346.951 | Q156: 43.577326 | R156: 0.5903702 | S156: 0.25845031 | T156: 0.017241767 | U156: 0.43521716 | V156: 0.32373621 | W156: 0.26909189 | X156: 0.073622348 | Y156: 0.34593183 | Z156: 0.29718654 | AA156: 0.001005854
A157: 156 | B157: 16.218217 | C157: -10.652583 | D157: -1.3936815 | E157: 34.994503 | F157: 7.0127394 | G157: 11.929935 | H157: 16.218217 | I157: 10.652583 | J157: 1.3936815 | K157: 34.994503 | L157: 7.0127394 | M157: 11.929935 | N157: 0.063190214 | O157: 30.198542 | P157: 323.96313 | Q157: 62.177679 | R157: 0.60545091 | S157: 0.43229333 | T157: 0.071231583 | U157: 0.44797799 | V157: 0.34230602 | W157: 0.24829845 | X157: 0.084116314 | Y157: 0.37874149 | Z157: 0.2774959 | AA157: 0.0014357782
A158: 157 | B158: 15.937913 | C158: -5.8956736 | D158: 0.31266334 | E158: 34.001658 | F158: 5.7694841 | G158: 11.754431 | H158: 15.937913 | I158: 5.8956736 | J158: 0.31266334 | K158: 34.001658 | L158: 5.7694841 | M158: 11.754431 | N158: 0.090367481 | O158: 38.741661 | P158: 320.28981 | Q158: 26.859157 | R158: 0.59486168 | S158: 0.238946 | T158: 0.015796376 | U158: 0.41964457 | V158: 0.28116078 | W158: 0.23863672 | X158: 0.12263393 | Y158: 0.48955178 | Z158: 0.27434946 | AA158: 0.00061943416
A159: 158 | B159: 16.175084 | C159: -6.8388454 | D159: -0.8135904 | E159: 33.348549 | F159: 5.2647086 | G159: 12.284767 | H159: 16.175084 | I159: 6.8388454 | J159: 0.8135904 | K159: 33.348549 | L159: 5.2647086 | M159: 12.284767 | N159: 0.082678847 | O159: 36.8218 | P159: 640.57961 | Q159: 6.6142938 | R159: 0.60382143 | S159: 0.27728176 | T159: 0.041484192 | U159: 0.40100641 | V159: 0.25633514 | W159: 0.26783237 | X159: 0.11173703 | Y159: 0.46464983 | Z159: 0.54869892 | AA159: 0.00015149911
A160: 159 | B160: 16.574511 | C160: -9.6893762 | D160: -3.0913955 | E160: 33.036504 | F160: 5.065256 | G160: 11.763311 | H160: 16.574511 | I160: 9.6893762 | J160: 3.0913955 | K160: 33.036504 | L160: 5.065256 | M160: 11.763311 | N160: 0.050230503 | O160: 26.243855 | P160: 435.82165 | Q160: 19.482701 | R160: 0.61891086 | S160: 0.39314324 | T160: 0.15829129 | U160: 0.39210141 | V160: 0.24652574 | W160: 0.2391256 | X160: 0.065748862 | Y160: 0.3274464 | Z160: 0.37331014 | AA160: 0.00044893647
A161: 160 | B161: 16.920555 | C161: -12.136592 | D161: -5.1162583 | E161: 32.660933 | F161: 4.9003286 | G161: 11.441788 | H161: 16.920555 | I161: 12.136592 | J161: 5.1162583 | K161: 32.660933 | L161: 4.9003286 | M161: 11.441788 | N161: 0.055408292 | O161: 29.016684 | P161: 328.43776 | Q161: 25.757041 | R161: 0.6319836 | S161: 0.49261173 | T161: 0.26212738 | U161: 0.38138349 | V161: 0.23841436 | W161: 0.22142534 | X161: 0.073087204 | Y161: 0.36341195 | Z161: 0.28132872 | AA161: 0.00059396011
A162: 161 | B162: 16.963395 | C162: -12.488014 | D162: -5.4118919 | E162: 32.979541 | F162: 5.0720614 | G162: 11.597138 | H162: 16.963395 | I162: 12.488014 | J162: 5.4118919 | K162: 32.979541 | L162: 5.0720614 | M162: 11.597138 | N162: 0.096847057 | O162: 45.114563 | P162: 938.46223 | Q162: 4.8488063 | R162: 0.633602 | S162: 0.50689549 | T162: 0.27728763 | U162: 0.39047581 | V162: 0.24686045 | W162: 0.22997758 | X162: 0.13181726 | Y162: 0.57221281 | Z162: 0.80385513 | AA162: 0.00011069205
A163: 162 | B163: 17.178456 | C163: -13.723445 | D163: -6.4047916 | E163: 33.286599 | F163: 4.9121056 | G163: 11.53911 | H163: 17.178456 | I163: 13.723445 | J163: 6.4047916 | K163: 33.286599 | L163: 4.9121056 | M163: 11.53911 | N163: 0.084864452 | O163: 42.558681 | P163: 985.31327 | Q163: 1.2904588 | R163: 0.6417265 | S163: 0.55711028 | T163: 0.32820408 | U163: 0.3992385 | V163: 0.23899357 | W163: 0.22678304 | X163: 0.11483463 | Y163: 0.53906123 | Z163: 0.84398615 | AA163: 2.8445236e-05
A164: 163 | B164: 17.573845 | C164: -14.663083 | D164: -6.4820584 | E164: 32.076612 | F164: 4.9475156 | G164: 10.810182 | H164: 17.573845 | I164: 14.663083 | J164: 6.4820584 | K164: 32.076612 | L164: 4.9475156 | M164: 10.810182 | N164: 0.026111249 | O164: 16.956099 | P164: 985.31327 | Q164: 18.447143 | R164: 0.65666335 | S164: 0.5953024 | T164: 0.33216636 | U164: 0.36470839 | V164: 0.24073509 | W164: 0.18665469 | X164: 0.031565286 | Y164: 0.20697765 | Z164: 0.84398615 | AA164: 0.00042500084
... A253: 252 | B253: 22.27679 | C253: 8.6238918 | D253: 12.050515 | E253: 37.730621 | F253: 2.4991779 | G253: 8.1742225 | H253: 22.27679 | I253: 8.6238918 | J253: 12.050515 | K253: 37.730621 | L253: 2.4991779 | M253: 8.1742225 | N253: 0.07360895 | O253: 21.956791 | P253: 184.90986 | Q253: 16.709723 | R253: 0.83432957 | S253: 0.34983601 | T253: 0.61771988 | U253: 0.52606026 | V253: 0.12032201 | W253: 0.041541965 | X253: 0.098882511 | Y253: 0.27184016 | Z253: 0.15838756 | AA253: 0.00038484251
A254: 253 | B254: NA | C254: NA | D254: NA | E254: NA | F254: NA | G254: NA | H254: NA | I254: NA | J254: NA | K254: NA | L254: NA | M254: NA | N254: 0.066998221 | O254: 22.582825 | P254: 369.81973 | Q254: 5.3933727 | R254: NA | S254: NA | T254: NA | U254: NA | V254: NA | W254: NA | X254: 0.089513301 | Y254: 0.27996026 | Z254: 0.31677512 | AA254: 0.00012327903
A255: 254 | B255: 21.777638 | C255: 7.5027753 | D255: 11.059172 | E255: 39.287275 | F255: 3.0534692 | G255: 8.8272351 | H255: 21.777638 | I255: 7.5027753 | J255: 11.059172 | K255: 39.287275 | L255: 3.0534692 | M255: 8.8272351 | N255: 0.076485507 | O255: 21.999382 | P255: 41.912902 | Q255: 158.31346 | R255: 0.81547278 | S255: 0.30426758 | T255: 0.56688328 | U255: 0.57048344 | V255: 0.14758293 | W255: 0.07749109 | X255: 0.10295938 | Y255: 0.2723926 | Z255: 0.03590118 | AA255: 0.0036578382
A256: 255 | B256: 21.729573 | C256: 6.9187588 | D256: 10.592925 | E256: 46.37412 | F256: 3.6441584 | G256: 10.510344 | H256: 21.729573 | I256: 6.9187588 | J256: 10.592925 | K256: 46.37412 | L256: 3.6441584 | M256: 10.510344 | N256: 0.059681132 | O256: 18.540543 | P256: 251.47741 | Q256: 8.3155129 | R256: 0.813657 | S256: 0.28052989 | T256: 0.54297388 | U256: 0.77272503 | V256: 0.17663395 | W256: 0.17014823 | X256: 0.079142986 | Y256: 0.22752901 | Z256: 0.21540708 | AA256: 0.0001908207
A257: 256 | B257: 21.697703 | C257: 6.7788755 | D257: 10.455633 | E257: 40.025009 | F257: 3.8704699 | G257: 10.166051 | H257: 21.697703 | I257: 6.7788755 | J257: 10.455633 | K257: 40.025009 | L257: 3.8704699 | M257: 10.166051 | N257: 0.11062743 | O257: 34.175461 | P257: 10.085993 | Q257: 575.11603 | R257: 0.81245302 | S257: 0.27484425 | T257: 0.53593348 | U257: 0.5915366 | V257: 0.1877643 | W257: 0.15119454 | X257: 0.15134781 | Y257: 0.43032494 | Z257: 0.0086393214 | AA257: 0.013291716
A258: 257 | B258: 21.392314 | C258: 8.0892365 | D258: 11.399672 | E258: 44.590125 | F258: 3.3636657 | G258: 9.566497 | H258: 21.392314 | I258: 8.0892365 | J258: 11.399672 | K258: 44.590125 | L258: 3.3636657 | M258: 9.566497 | N258: 0.085336462 | O258: 23.67334 | P258: 251.47741 | Q258: 21.047674 | R258: 0.80091614 | S258: 0.32810463 | T258: 0.58434432 | U258: 0.7218141 | V258: 0.16283888 | W258: 0.11818835 | X258: 0.1155036 | Y258: 0.29410501 | Z258: 0.21540708 | AA258: 0.00048510889
A259: 258 | B259: 21.367986 | C259: 7.9450249 | D259: 11.28142 | E259: 38.007288 | F259: 3.1782992 | G259: 8.7774016 | H259: 21.367986 | I259: 7.9450249 | J259: 11.28142 | K259: 38.007288 | L259: 3.1782992 | M259: 8.7774016 | N259: 0.085336462 | O259: 24.514526 | P259: 41.912902 | Q259: 139.9752 | R259: 0.79999709 | S259: 0.32224307 | T259: 0.57828026 | U259: 0.53395566 | V259: 0.15372226 | W259: 0.074747695 | X259: 0.1155036 | Y259: 0.3050158 | Z259: 0.03590118 | AA259: 0.0032339718
A260: 259 | B260: 22.804405 | C260: 2.8357581 | D260: 7.9908492 | E260: 37.356227 | F260: 3.6941647 | G260: 10.246546 | H260: 22.804405 | I260: 2.8357581 | J260: 7.9908492 | K260: 37.356227 | L260: 3.6941647 | M260: 10.246546 | N260: 0.061290737 | O260: 19.313704 | P260: 462.27466 | Q260: 20.680079 | R260: 0.85426163 | S260: 0.11457397 | T260: 0.40953799 | U260: 0.51537596 | V260: 0.17909333 | W260: 0.15562585 | X260: 0.081424236 | Y260: 0.23755745 | Z260: 0.3959689 | AA260: 0.00047661238
A261: 260 | B261: 22.664254 | C261: 2.8373085 | D261: 7.9727057 | E261: 39.846279 | F261: 3.7951952 | G261: 10.175942 | H261: 22.664254 | I261: 2.8373085 | J261: 7.9727057 | K261: 39.846279 | L261: 3.7951952 | M261: 10.175942 | N261: 0.069271766 | O261: 20.590017 | P261: 170.11707 | Q261: 36.858633 | R261: 0.84896704 | S261: 0.11463698 | T261: 0.40860758 | U261: 0.58643607 | V261: 0.18406217 | W261: 0.15173903 | X261: 0.092735536 | Y261: 0.25411214 | Z261: 0.14571655 | AA261: 0.0008505597
A262: 261 | B262: 22.666679 | C262: 2.8146883 | D262: 7.9278276 | E262: 37.914894 | F262: 3.4530292 | G262: 9.6270856 | H262: 22.666679 | I262: 2.8146883 | J262: 7.9278276 | K262: 37.914894 | L262: 3.4530292 | M262: 9.6270856 | N262: 0.073546283 | O262: 25.224392 | P262: 340.23415 | Q262: 15.518493 | R262: 0.84905866 | S262: 0.11371757 | T262: 0.40630621 | U262: 0.53131897 | V262: 0.16723391 | W262: 0.12152382 | X262: 0.098793695 | Y262: 0.31422325 | Z262: 0.29143311 | AA262: 0.00035730869
A263: 262 | B263: 22.541613 | C263: 3.3795119 | D263: 8.25778 | E263: 37.933704 | F263: 3.0526253 | G263: 9.1724505 | H263: 22.541613 | I263: 3.3795119 | J263: 8.25778 | K263: 37.933704 | L263: 3.0526253 | M263: 9.1724505 | N263: 0.069982223 | O263: 22.504364 | P263: 340.23415 | Q263: 7.1097999 | R263: 0.84433396 | S263: 0.13667515 | T263: 0.42322635 | U263: 0.53185578 | V263: 0.14754142 | W263: 0.096495615 | X263: 0.093742448 | Y263: 0.27894257 | Z263: 0.29143311 | AA263: 0.00016295213
A264: 263 | B264: 23.040584 | C264: 1.7141473 | D264: 7.1915075 | E264: 37.811524 | F264: 3.976334 | G264: 10.007097 | H264: 23.040584 | I264: 1.7141473 | J264: 7.1915075 | K264: 37.811524 | L264: 3.976334 | M264: 10.007097 | N264: 0.05719221 | O264: 26.892544 | P264: 340.23415 | Q264: 2.8112217 | R264: 0.86318391 | S264: 0.068985448 | T264: 0.36854731 | U264: 0.52836904 | V264: 0.19297086 | W264: 0.14244388 | X264: 0.075615503 | Y264: 0.33586036 | Z264: 0.29143311 | AA264: 6.3595795e-05
A265: 264 | B265: 22.896605 | C265: 0.46508591 | D265: 6.3065671 | E265: 38.600379 | F265: 4.5817951 | G265: 11.619257 | H265: 22.896605 | I265: 0.46508591 | J265: 6.3065671 | K265: 38.600379 | L265: 4.5817951 | M265: 11.619257 | N265: 0.038209975 | O265: 15.989592 | P265: 458.57646 | Q265: 19.502571 | R265: 0.85774473 | S265: 0.018216628 | T265: 0.32316707 | U265: 0.55088107 | V265: 0.22274838 | W265: 0.23119525 | X265: 0.048712488 | Y265: 0.19444137 | Z265: 0.39280115 | AA265: 0.00044939575
...

Sheet size_scores
A1: EST_ID | B1: Area_Ha | C1: Decile | D1: Rank | F1: decile ranges
A2: 1 | B2: 91.553166 | C2: =IF(B2<$G$2, $F$2, IF(B2<$G$3, $F$3, IF(B2<$G$4, $F$4, IF(B2<$G$5, $F$5, IF(B2<$G$6, $F$6, IF(B2<$G$7, $F$7, IF(B2<$G$8, $F$8, IF(B2<$G$9, $F$9, IF(B2<$G$10, $F$10, $F$11))))))))) -> 0.8 | D2: =C2*10 -> 8 | F2: 0.1 | G2: =PERCENTILE($B$2:$B$753, 0.1) -> 2.554563
A3: 2 | B3: 122.52264 | C3: =IF(B3<$G$2, $F$2, IF(B3<$G$3, $F$3, IF(B3<$G$4, $F$4, IF(B3<$G$5, $F$5, IF(B3<$G$6, $F$6, IF(B3<$G$7, $F$7, IF(B3<$G$8, $F$8, IF(B3<$G$9, $F$9, IF(B3<$G$10, $F$10, $F$11))))))))) -> 0.9 | D3: =C3*10 -> 9 | F3: 0.2 | G3: =PERCENTILE($B$2:$B$753, 0.2) -> 5.4300293
A4: 3 | B4: 97.451312 | C4: =IF(B4<$G$2, $F$2, IF(B4<$G$3, $F$3, IF(B4<$G$4, $F$4, IF(B4<$G$5, $F$5, IF(B4<$G$6, $F$6, IF(B4<$G$7, $F$7, IF(B4<$G$8, $F$8, IF(B4<$G$9, $F$9, IF(B4<$G$10, $F$10, $F$11))))))))) -> 0.8 | D4: =C4*10 -> 8 | F4: 0.3 | G4: =PERCENTILE($B$2:$B$753, 0.3) -> 10.382761
A5: 4 | B5: 113.93918 | C5: =IF(B5<$G$2, $F$2, IF(B5<$G$3, $F$3, IF(B5<$G$4, $F$4, IF(B5<$G$5, $F$5, IF(B5<$G$6, $F$6, IF(B5<$G$7, $F$7, IF(B5<$G$8, $F$8, IF(B5<$G$9, $F$9, IF(B5<$G$10, $F$10, $F$11))))))))) -> 0.9 | D5: =C5*10 -> 9 | F5: 0.4 | G5: =PERCENTILE($B$2:$B$753, 0.4) -> 18.102797
A6: 5 | B6: 115.35458 | C6: =IF(B6<$G$2, $F$2, IF(B6<$G$3, $F$3, IF(B6<$G$4, $F$4, IF(B6<$G$5, $F$5, IF(B6<$G$6, $F$6, IF(B6<$G$7, $F$7, IF(B6<$G$8, $F$8, IF(B6<$G$9, $F$9, IF(B6<$G$10, $F$10, $F$11))))))))) -> 0.9 | D6: =C6*10 -> 9 | F6: 0.5 | G6: =PERCENTILE($B$2:$B$753, 0.5) -> 25.764637
A7: 6 | B7: 176.06916 | C7: =IF(B7<$G$2, $F$2, IF(B7<$G$3, $F$3, IF(B7<$G$4, $F$4, IF(B7<$G$5, $F$5, IF(B7<$G$6, $F$6, IF(B7<$G$7, $F$7, IF(B7<$G$8, $F$8, IF(B7<$G$9, $F$9, IF(B7<$G$10, $F$10, $F$11))))))))) -> 0.9 | D7: =C7*10 -> 9 | F7: 0.6 | G7: =PERCENTILE($B$2:$B$753, 0.6) -> 41.138725
A8: 7 | B8: 17.807913 | C8: =IF(B8<$G$2, $F$2, IF(B8<$G$3, $F$3, IF(B8<$G$4, $F$4, IF(B8<$G$5, $F$5, IF(B8<$G$6, $F$6, IF(B8<$G$7, $F$7, IF(B8<$G$8, $F$8, IF(B8<$G$9, $F$9, IF(B8<$G$10, $F$10, $F$11))))))))) -> 0.4 | D8: =C8*10 -> 4 | F8: 0.7 | G8: =PERCENTILE($B$2:$B$753, 0.7) -> 64.053172
A9: 8 | B9: 48.64952 | C9: =IF(B9<$G$2, $F$2, IF(B9<$G$3, $F$3, IF(B9<$G$4, $F$4, IF(B9<$G$5, $F$5, IF(B9<$G$6, $F$6, IF(B9<$G$7, $F$7, IF(B9<$G$8, $F$8, IF(B9<$G$9, $F$9, IF(B9<$G$10, $F$10, $F$11))))))))) -> 0.7 | D9: =C9*10 -> 7 | F9: 0.8 | G9: =PERCENTILE($B$2:$B$753, 0.8) -> 113.45374
A10: 9 | B10: 148.57937 | C10: =IF(B10<$G$2, $F$2, IF(B10<$G$3, $F$3, IF(B10<$G$4, $F$4, IF(B10<$G$5, $F$5, IF(B10<$G$6, $F$6, IF(B10<$G$7, $F$7, IF(B10<$G$8, $F$8, IF(B10<$G$9, $F$9, IF(B10<$G$10, $F$10, $F$11))))))))) -> 0.9 | D10: =C10*10 -> 9 | F10: 0.9 | G10: =PERCENTILE($B$2:$B$753, 0.9) -> 357.83049
A11: 10 | B11: 118.31326 | C11: =IF(B11<$G$2, $F$2, IF(B11<$G$3, $F$3, IF(B11<$G$4, $F$4, IF(B11<$G$5, $F$5, IF(B11<$G$6, $F$6, IF(B11<$G$7, $F$7, IF(B11<$G$8, $F$8, IF(B11<$G$9, $F$9, IF(B11<$G$10, $F$10, $F$11))))))))) -> 0.9 | D11: =C11*10 -> 9 | F11: 1 | G11: =PERCENTILE($B$2:$B$753, 1) -> 43264.32
A12: 11 | B12: 288.65926 | C12: =IF(B12<$G$2, $F$2, IF(B12<$G$3, $F$3, IF(B12<$G$4, $F$4, IF(B12<$G$5, $F$5, IF(B12<$G$6, $F$6, IF(B12<$G$7, $F$7, IF(B12<$G$8, $F$8, IF(B12<$G$9, $F$9, IF(B12<$G$10, $F$10, $F$11))))))))) -> 0.9 | D12: =C12*10 -> 9
A13: 12 | B13: 17.887168 | C13: =IF(B13<$G$2, $F$2, IF(B13<$G$3, $F$3, IF(B13<$G$4, $F$4, IF(B13<$G$5, $F$5, IF(B13<$G$6, $F$6, IF(B13<$G$7, $F$7, IF(B13<$G$8, $F$8, IF(B13<$G$9, $F$9, IF(B13<$G$10, $F$10, $F$11))))))))) -> 0.4 | D13: =C13*10 -> 4
A14: 13 | B14: 777.94496 | C14: =IF(B14<$G$2, $F$2, IF(B14<$G$3, $F$3, IF(B14<$G$4, $F$4, IF(B14<$G$5, $F$5, IF(B14<$G$6, $F$6, IF(B14<$G$7, $F$7, IF(B14<$G$8, $F$8, IF(B14<$G$9, $F$9, IF(B14<$G$10, $F$10, $F$11))))))))) -> 1 | D14: =C14*10 -> 10 | F14: ranked high to low
A15: 14 | B15: 392.72086 | C15: =IF(B15<$G$2, $F$2, IF(B15<$G$3, $F$3, IF(B15<$G$4, $F$4, IF(B15<$G$5, $F$5, IF(B15<$G$6, $F$6, IF(B15<$G$7, $F$7, IF(B15<$G$8, $F$8, IF(B15<$G$9, $F$9, IF(B15<$G$10, $F$10, $F$11))))))))) -> 1 | D15: =C15*10 -> 10 | F15: 1 = largest
A16: 15 | B16: 897.87741 | C16: =IF(B16<$G$2, $F$2, IF(B16<$G$3, $F$3, IF(B16<$G$4, $F$4, IF(B16<$G$5, $F$5, IF(B16<$G$6, $F$6, IF(B16<$G$7, $F$7, IF(B16<$G$8, $F$8, IF(B16<$G$9, $F$9, IF(B16<$G$10, $F$10, $F$11))))))))) -> 1 | D16: =C16*10 -> 10 | F16: 10 = smallest
A17: 16 | B17: 610.45355 | C17: =IF(B17<$G$2, $F$2, IF(B17<$G$3, $F$3, IF(B17<$G$4, $F$4, IF(B17<$G$5, $F$5, IF(B17<$G$6, $F$6, IF(B17<$G$7, $F$7, IF(B17<$G$8, $F$8, IF(B17<$G$9, $F$9, IF(B17<$G$10, $F$10, $F$11))))))))) -> 1 | D17: =C17*10 -> 10
A18: 17 | B18: 78.540008 | C18: =IF(B18<$G$2, $F$2, IF(B18<$G$3, $F$3, IF(B18<$G$4, $F$4, IF(B18<$G$5, $F$5, IF(B18<$G$6, $F$6, IF(B18<$G$7, $F$7, IF(B18<$G$8, $F$8, IF(B18<$G$9, $F$9, IF(B18<$G$10, $F$10, $F$11))))))))) -> 0.8 | D18: =C18*10 -> 8
A19: 18 | B19: 76.314305 | C19: =IF(B19<$G$2, $F$2, IF(B19<$G$3, $F$3, IF(B19<$G$4, $F$4, IF(B19<$G$5, $F$5, IF(B19<$G$6, $F$6, IF(B19<$G$7, $F$7, IF(B19<$G$8, $F$8, IF(B19<$G$9, $F$9, IF(B19<$G$10, $F$10, $F$11))))))))) -> 0.8 | D19: =C19*10 -> 8
A20: 19 | B20: 46.034564 | C20: =IF(B20<$G$2, $F$2, IF(B20<$G$3, $F$3, IF(B20<$G$4, $F$4, IF(B20<$G$5, $F$5, IF(B20<$G$6, $F$6, IF(B20<$G$7, $F$7, IF(B20<$G$8, $F$8, IF(B20<$G$9, $F$9, IF(B20<$G$10, $F$10, $F$11))))))))) -> 0.7 | D20: =C20*10 -> 7
A21: 20 | B21: 39.004147 | C21: =IF(B21<$G$2, $F$2, IF(B21<$G$3, $F$3, IF(B21<$G$4, $F$4, IF(B21<$G$5, $F$5, IF(B21<$G$6, $F$6, IF(B21<$G$7, $F$7, IF(B21<$G$8, $F$8, IF(B21<$G$9, $F$9, IF(B21<$G$10, $F$10, $F$11))))))))) -> 0.6 | D21: =C21*10 -> 6
A22: 21 | B22: 31.815892 | C22: =IF(B22<$G$2, $F$2, IF(B22<$G$3, $F$3, IF(B22<$G$4, $F$4, IF(B22<$G$5, $F$5, IF(B22<$G$6, $F$6, IF(B22<$G$7, $F$7, IF(B22<$G$8, $F$8, IF(B22<$G$9, $F$9, IF(B22<$G$10, $F$10, $F$11))))))))) -> 0.6 | D22: =C22*10 -> 6
A23: 22 | B23: 294.34733 | C23: =IF(B23<$G$2, $F$2, IF(B23<$G$3, $F$3, IF(B23<$G$4, $F$4, IF(B23<$G$5, $F$5, IF(B23<$G$6, $F$6, IF(B23<$G$7, $F$7, IF(B23<$G$8, $F$8, IF(B23<$G$9, $F$9, IF(B23<$G$10, $F$10, $F$11))))))))) -> 0.9 | D23: =C23*10 -> 9
A24: 23 | B24: 81.966238 | C24: =IF(B24<$G$2, $F$2, IF(B24<$G$3, $F$3, IF(B24<$G$4, $F$4, IF(B24<$G$5, $F$5, IF(B24<$G$6, $F$6, IF(B24<$G$7, $F$7, IF(B24<$G$8, $F$8, IF(B24<$G$9, $F$9, IF(B24<$G$10, $F$10, $F$11))))))))) -> 0.8 | D24: =C24*10 -> 8
A25: 24 | B25: 219.70703 | C25: =IF(B25<$G$2, $F$2, IF(B25<$G$3, $F$3, IF(B25<$G$4, $F$4, IF(B25<$G$5, $F$5, IF(B25<$G$6, $F$6, IF(B25<$G$7, $F$7, IF(B25<$G$8, $F$8, IF(B25<$G$9, $F$9, IF(B25<$G$10, $F$10, $F$11))))))))) -> 0.9 | D25: =C25*10 -> 9
A26: 25 | B26: 868.92185 | C26: =IF(B26<$G$2, $F$2, IF(B26<$G$3, $F$3, IF(B26<$G$4, $F$4, IF(B26<$G$5, $F$5, IF(B26<$G$6, $F$6, IF(B26<$G$7, $F$7, IF(B26<$G$8, $F$8, IF(B26<$G$9, $F$9, IF(B26<$G$10, $F$10, $F$11))))))))) -> 1 | D26: =C26*10 -> 10
A27: 26 | B27: 18.518564 | C27: =IF(B27<$G$2, $F$2, IF(B27<$G$3, $F$3, IF(B27<$G$4, $F$4, IF(B27<$G$5, $F$5, IF(B27<$G$6, $F$6, IF(B27<$G$7, $F$7, IF(B27<$G$8, $F$8, IF(B27<$G$9, $F$9, IF(B27<$G$10, $F$10, $F$11))))))))) -> 0.5 | D27: =C27*10 -> 5
A28: 27 | B28: 8.9218758 | C28: =IF(B28<$G$2, $F$2, IF(B28<$G$3, $F$3, IF(B28<$G$4, $F$4, IF(B28<$G$5, $F$5, IF(B28<$G$6, $F$6, IF(B28<$G$7, $F$7, IF(B28<$G$8, $F$8, IF(B28<$G$9, $F$9, IF(B28<$G$10, $F$10, $F$11))))))))) -> 0.3 | D28: =C28*10 -> 3
... A753: 3030 | B753: 50.987391 | C753: =IF(B753<$G$2, $F$2, IF(B753<$G$3, $F$3, IF(B753<$G$4, $F$4, IF(B753<$G$5, $F$5, IF(B753<$G$6, $F$6, IF(B753<$G$7, $F$7, IF(B753<$G$8, $F$8, IF(B753<$G$9, $F$9, IF(B753<$G$10, $F$10, $F$11))))))))) -> 0.7 | D753: =C753*10 -> 7

Sheet climate_scores
A1: EST_ID | B1: mean.tas | C1: mean.pr | D1: SD.tas | E1: SD.pr | F1: ES.tas | G1: ES.pr | H1: cumulative.score | I1: rank
A2: 1 | B2: =estuary_data!U2*weights!$C$2 -> 0.036221763 | C2: =estuary_data!R2*weights!$C$5 -> 0.065469908 | D2: =estuary_data!V2*weights!$C$3 -> 0.030204007 | E2: =estuary_data!S2*weights!$C$6 -> 0.032749069 | F2: =estuary_data!W2*weights!$C$4 -> 0.078468729 | G2: =estuary_data!T2*weights!$C$7 -> 0.034495986 | H2: =SUM(B2:G2) -> 0.27760946 | I2: =IF(H2>$L$5/10*9,"1",IF(H2>$L$5/10*8,"2",IF(H2>$L$5/10*7,"3",IF(H2>$L$5/10*6,"4",IF(H2>$L$5/10*5,"5",IF(H2>$L$5/10*4,"6",IF(H2>$L$5/10*3,"7",IF(H2>$L$5/10*2,"8",IF(H2>$L$5/10,"9","10"))))))))) -> 6
A3: 2 | B3: =estuary_data!U3*weights!$C$2 -> 0.039340044 | C3: =estuary_data!R3*weights!$C$5 -> 0.078058818 | D3: =estuary_data!V3*weights!$C$3 -> 0.034313388 | E3: =estuary_data!S3*weights!$C$6 -> 0.024866237 | F3: =estuary_data!W3*weights!$C$4 -> 0.091613637 | G3: =estuary_data!T3*weights!$C$7 -> 0.010771004 | H3: =SUM(B3:G3) -> 0.27896313 | I3: =IF(H3>$L$5/10*9,"1",IF(H3>$L$5/10*8,"2",IF(H3>$L$5/10*7,"3",IF(H3>$L$5/10*6,"4",IF(H3>$L$5/10*5,"5",IF(H3>$L$5/10*4,"6",IF(H3>$L$5/10*3,"7",IF(H3>$L$5/10*2,"8",IF(H3>$L$5/10,"9","10"))))))))) -> 6
A4: 3 | B4: =estuary_data!U4*weights!$C$2 -> 0.077215604 | C4: =estuary_data!R4*weights!$C$5 -> 0.082702109 | D4: =estuary_data!V4*weights!$C$3 -> 0.041534144 | E4: =estuary_data!S4*weights!$C$6 -> 0.011893398 | F4: =estuary_data!W4*weights!$C$4 -> 0.17653977 | G4: =estuary_data!T4*weights!$C$7 -> 0.061502535 | H4: =SUM(B4:G4) -> 0.45138756 | I4: =IF(H4>$L$5/10*9,"1",IF(H4>$L$5/10*8,"2",IF(H4>$L$5/10*7,"3",IF(H4>$L$5/10*6,"4",IF(H4>$L$5/10*5,"5",IF(H4>$L$5/10*4,"6",IF(H4>$L$5/10*3,"7",IF(H4>$L$5/10*2,"8",IF(H4>$L$5/10,"9","10"))))))))) -> 4
A5: 4 | B5: =estuary_data!U5*weights!$C$2 -> 0.077453701 | C5: =estuary_data!R5*weights!$C$5 -> 0.082071148 | D5: =estuary_data!V5*weights!$C$3 -> 0.037653205 | E5: =estuary_data!S5*weights!$C$6 -> 0.017436314 | F5: =estuary_data!W5*weights!$C$4 -> 0.16169562 | G5: =estuary_data!T5*weights!$C$7 -> 0.0713837 | H5: =SUM(B5:G5) -> 0.44769368 | I5: =IF(H5>$L$5/10*9,"1",IF(H5>$L$5/10*8,"2",IF(H5>$L$5/10*7,"3",IF(H5>$L$5/10*6,"4",IF(H5>$L$5/10*5,"5",IF(H5>$L$5/10*4,"6",IF(H5>$L$5/10*3,"7",IF(H5>$L$5/10*2,"8",IF(H5>$L$5/10,"9","10"))))))))) -> 4 | K5: max | L5: 0.66432 | M5: all values scored and scaled according to max
A6: 5 | B6: =estuary_data!U6*weights!$C$2 -> 0.037216136 | C6: =estuary_data!R6*weights!$C$5 -> 0.075366008 | D6: =estuary_data!V6*weights!$C$3 -> 0.031882774 | E6: =estuary_data!S6*weights!$C$6 -> 0.027566482 | F6: =estuary_data!W6*weights!$C$4 -> 0.081691309 | G6: =estuary_data!T6*weights!$C$7 -> 0.018346074 | H6: =SUM(B6:G6) -> 0.27206878 | I6: =IF(H6>$L$5/10*9,"1",IF(H6>$L$5/10*8,"2",IF(H6>$L$5/10*7,"3",IF(H6>$L$5/10*6,"4",IF(H6>$L$5/10*5,"5",IF(H6>$L$5/10*4,"6",IF(H6>$L$5/10*3,"7",IF(H6>$L$5/10*2,"8",IF(H6>$L$5/10,"9","10"))))))))) -> 6
A7: 6 | B7: =estuary_data!U7*weights!$C$2 -> 0.036426689 | C7: =estuary_data!R7*weights!$C$5 -> 0.070952559 | D7: =estuary_data!V7*weights!$C$3 -> 0.028388438 | E7: =estuary_data!S7*weights!$C$6 -> 0.032611192 | F7: =estuary_data!W7*weights!$C$4 -> 0.077753165 | G7: =estuary_data!T7*weights!$C$7 -> 0.0313881 | H7: =SUM(B7:G7) -> 0.27752014 | I7: =IF(H7>$L$5/10*9,"1",IF(H7>$L$5/10*8,"2",IF(H7>$L$5/10*7,"3",IF(H7>$L$5/10*6,"4",IF(H7>$L$5/10*5,"5",IF(H7>$L$5/10*4,"6",IF(H7>$L$5/10*3,"7",IF(H7>$L$5/10*2,"8",IF(H7>$L$5/10,"9","10"))))))))) -> 6
A8: 7 | B8: =estuary_data!U8*weights!$C$2 -> 0.048897568 | C8: =estuary_data!R8*weights!$C$5 -> 0.10234955 | D8: =estuary_data!V8*weights!$C$3 -> 0.018926972 | E8: =estuary_data!S8*weights!$C$6 -> 0.0065238878 | F8: =estuary_data!W8*weights!$C$4 -> 0.059582979 | G8: =estuary_data!T8*weights!$C$7 -> 0.10469248 | H8: =SUM(B8:G8) -> 0.34097344 | I8: =IF(H8>$L$5/10*9,"1",IF(H8>$L$5/10*8,"2",IF(H8>$L$5/10*7,"3",IF(H8>$L$5/10*6,"4",IF(H8>$L$5/10*5,"5",IF(H8>$L$5/10*4,"6",IF(H8>$L$5/10*3,"7",IF(H8>$L$5/10*2,"8",IF(H8>$L$5/10,"9","10"))))))))) -> 5
A9: 8 | B9: =estuary_data!U9*weights!$C$2 -> 0.048556975 | C9: =estuary_data!R9*weights!$C$5 -> 0.10246592 | D9: =estuary_data!V9*weights!$C$3 -> 0.019546557 | E9: =estuary_data!S9*weights!$C$6 -> 0.0060577402 | F9: =estuary_data!W9*weights!$C$4 -> 0.054743845 | G9: =estuary_data!T9*weights!$C$7 -> 0.041079166 | H9: =SUM(B9:G9) -> 0.2724502 | I9: =IF(H9>$L$5/10*9,"1",IF(H9>$L$5/10*8,"2",IF(H9>$L$5/10*7,"3",IF(H9>$L$5/10*6,"4",IF(H9>$L$5/10*5,"5",IF(H9>$L$5/10*4,"6",IF(H9>$L$5/10*3,"7",IF(H9>$L$5/10*2,"8",IF(H9>$L$5/10,"9","10"))))))))) -> 6 | K9: ranked high to low
A10: 9 | B10: =estuary_data!U10*weights!$C$2 -> 0.054477103 | C10: =estuary_data!R10*weights!$C$5 -> 0.089253421 | D10: =estuary_data!V10*weights!$C$3 -> 0.0371493 | E10: =estuary_data!S10*weights!$C$6 -> 0.012738096 | F10: =estuary_data!W10*weights!$C$4 -> 0.11794284 | G10: =estuary_data!T10*weights!$C$7 -> 0.017273018 | H10: =SUM(B10:G10) -> 0.32883378 | I10: =IF(H10>$L$5/10*9,"1",IF(H10>$L$5/10*8,"2",IF(H10>$L$5/10*7,"3",IF(H10>$L$5/10*6,"4",IF(H10>$L$5/10*5,"5",IF(H10>$L$5/10*4,"6",IF(H10>$L$5/10*3,"7",IF(H10>$L$5/10*2,"8",IF(H10>$L$5/10,"9","10"))))))))) -> 6 | K10: 1 = highest climate impact
A11: 10 | B11: =estuary_data!U11*weights!$C$2 -> 0.042062486 | C11: =estuary_data!R11*weights!$C$5 -> 0.081732906 | D11: =estuary_data!V11*weights!$C$3 -> 0.033436831 | E11: =estuary_data!S11*weights!$C$6 -> 0.019442694 | F11: =estuary_data!W11*weights!$C$4 -> 0.096101587 | G11: =estuary_data!T11*weights!$C$7 -> 0.00069297624 | H11: =SUM(B11:G11) -> 0.27346948 | I11: =IF(H11>$L$5/10*9,"1",IF(H11>$L$5/10*8,"2",IF(H11>$L$5/10*7,"3",IF(H11>$L$5/10*6,"4",IF(H11>$L$5/10*5,"5",IF(H11>$L$5/10*4,"6",IF(H11>$L$5/10*3,"7",IF(H11>$L$5/10*2,"8",IF(H11>$L$5/10,"9","10"))))))))) -> 6 | K11: 10 = lowest climate impact
A12: 11 | B12: =estuary_data!U12*weights!$C$2 -> 0.036434853 | C12: =estuary_data!R12*weights!$C$5 -> 0.065497489 | D12: =estuary_data!V12*weights!$C$3 -> 0.030622034 | E12: =estuary_data!S12*weights!$C$6 -> 0.03223966 | F12: =estuary_data!W12*weights!$C$4 -> 0.079701268 | G12: =estuary_data!T12*weights!$C$7 -> 0.033393732 | H12: =SUM(B12:G12) -> 0.27788904 | I12: =IF(H12>$L$5/10*9,"1",IF(H12>$L$5/10*8,"2",IF(H12>$L$5/10*7,"3",IF(H12>$L$5/10*6,"4",IF(H12>$L$5/10*5,"5",IF(H12>$L$5/10*4,"6",IF(H12>$L$5/10*3,"7",IF(H12>$L$5/10*2,"8",IF(H12>$L$5/10,"9","10"))))))))) -> 6
A13: 12 | B13: =estuary_data!U13*weights!$C$2 -> 0.068460807 | C13: =estuary_data!R13*weights!$C$5 -> 0.058447276 | D13: =estuary_data!V13*weights!$C$3 -> 0.058122311 | E13: =estuary_data!S13*weights!$C$6 -> 0.031506382 | F13: =estuary_data!W13*weights!$C$4 -> 0.21317066 | G13: =estuary_data!T13*weights!$C$7 -> 0.037701744 | H13: =SUM(B13:G13) -> 0.46740918 | I13: =IF(H13>$L$5/10*9,"1",IF(H13>$L$5/10*8,"2",IF(H13>$L$5/10*7,"3",IF(H13>$L$5/10*6,"4",IF(H13>$L$5/10*5,"5",IF(H13>$L$5/10*4,"6",IF(H13>$L$5/10*3,"7",IF(H13>$L$5/10*2,"8",IF(H13>$L$5/10,"9","10"))))))))) -> 3
A14: 13 | B14: =estuary_data!U14*weights!$C$2 -> 0.052729949 | C14: =estuary_data!R14*weights!$C$5 -> 0.076287046 | D14: =estuary_data!V14*weights!$C$3 -> 0.036882433 | E14: =estuary_data!S14*weights!$C$6 -> 0.0096483158 | F14: =estuary_data!W14*weights!$C$4 -> 0.12933216 | G14: =estuary_data!T14*weights!$C$7 -> 0.012458399 | H14: =SUM(B14:G14) -> 0.3173383 | I14: =IF(H14>$L$5/10*9,"1",IF(H14>$L$5/10*8,"2",IF(H14>$L$5/10*7,"3",IF(H14>$L$5/10*6,"4",IF(H14>$L$5/10*5,"5",IF(H14>$L$5/10*4,"6",IF(H14>$L$5/10*3,"7",IF(H14>$L$5/10*2,"8",IF(H14>$L$5/10,"9","10"))))))))) -> 6
A15: 14 | B15: =estuary_data!U15*weights!$C$2 -> 0.055665166 | C15: =estuary_data!R15*weights!$C$5 -> 0.061984391 | D15: =estuary_data!V15*weights!$C$3 -> 0.037786046 | E15: =estuary_data!S15*weights!$C$6 -> 0.01667104 | F15: =estuary_data!W15*weights!$C$4 -> 0.13572805 | G15: =estuary_data!T15*weights!$C$7 -> 0.006995745 | H15: =SUM(B15:G15) -> 0.31483044 | I15: =IF(H15>$L$5/10*9,"1",IF(H15>$L$5/10*8,"2",IF(H15>$L$5/10*7,"3",IF(H15>$L$5/10*6,"4",IF(H15>$L$5/10*5,"5",IF(H15>$L$5/10*4,"6",IF(H15>$L$5/10*3,"7",IF(H15>$L$5/10*2,"8",IF(H15>$L$5/10,"9","10"))))))))) -> 6
A16: 15 | B16: =estuary_data!U16*weights!$C$2 -> 0.050114485 | C16: =estuary_data!R16*weights!$C$5 -> 0.090211616 | D16: =estuary_data!V16*weights!$C$3 -> 0.036120397 | E16: =estuary_data!S16*weights!$C$6 -> 0.010817255 | F16: =estuary_data!W16*weights!$C$4 -> 0.12385928 | G16: =estuary_data!T16*weights!$C$7 -> 0.016403024 | H16: =SUM(B16:G16) -> 0.32752606 | I16: =IF(H16>$L$5/10*9,"1",IF(H16>$L$5/10*8,"2",IF(H16>$L$5/10*7,"3",IF(H16>$L$5/10*6,"4",IF(H16>$L$5/10*5,"5",IF(H16>$L$5/10*4,"6",IF(H16>$L$5/10*3,"7",IF(H16>$L$5/10*2,"8",IF(H16>$L$5/10,"9","10"))))))))) -> 6
A17: 16 | B17: =estuary_data!U17*weights!$C$2 -> 0.036804793 | C17: =estuary_data!R17*weights!$C$5 -> 0.071136251 | D17: =estuary_data!V17*weights!$C$3 -> 0.029870783 | E17: =estuary_data!S17*weights!$C$6 -> 0.030850135 | F17: =estuary_data!W17*weights!$C$4 -> 0.078572452 | G17: =estuary_data!T17*weights!$C$7 -> 0.027798783 | H17: =SUM(B17:G17) -> 0.2750332 | I17: =IF(H17>$L$5/10*9,"1",IF(H17>$L$5/10*8,"2",IF(H17>$L$5/10*7,"3",IF(H17>$L$5/10*6,"4",IF(H17>$L$5/10*5,"5",IF(H17>$L$5/10*4,"6",IF(H17>$L$5/10*3,"7",IF(H17>$L$5/10*2,"8",IF(H17>$L$5/10,"9","10"))))))))) -> 6
A18: 17 | B18: =estuary_data!U18*weights!$C$2 -> 0.068794873 | C18: =estuary_data!R18*weights!$C$5 -> 0.038581242 | D18: =estuary_data!V18*weights!$C$3 -> 0.058185488 | E18: =estuary_data!S18*weights!$C$6 -> 0.025557671 | F18: =estuary_data!W18*weights!$C$4 -> 0.21680585 | G18: =estuary_data!T18*weights!$C$7 -> 0.032441137 | H18: =SUM(B18:G18) -> 0.44036626 | I18: =IF(H18>$L$5/10*9,"1",IF(H18>$L$5/10*8,"2",IF(H18>$L$5/10*7,"3",IF(H18>$L$5/10*6,"4",IF(H18>$L$5/10*5,"5",IF(H18>$L$5/10*4,"6",IF(H18>$L$5/10*3,"7",IF(H18>$L$5/10*2,"8",IF(H18>$L$5/10,"9","10"))))))))) -> 4
A19: 18 | B19: =estuary_data!U19*weights!$C$2 -> 0.04947856 | C19: =estuary_data!R19*weights!$C$5 -> 0.090966554 | D19: =estuary_data!V19*weights!$C$3 -> 0.03644365 | E19: =estuary_data!S19*weights!$C$6 -> 0.011077254 | F19: =estuary_data!W19*weights!$C$4 -> 0.11421251 | G19: =estuary_data!T19*weights!$C$7 -> 0.051857289 | H19: =SUM(B19:G19) -> 0.35403581 | I19: =IF(H19>$L$5/10*9,"1",IF(H19>$L$5/10*8,"2",IF(H19>$L$5/10*7,"3",IF(H19>$L$5/10*6,"4",IF(H19>$L$5/10*5,"5",IF(H19>$L$5/10*4,"6",IF(H19>$L$5/10*3,"7",IF(H19>$L$5/10*2,"8",IF(H19>$L$5/10,"9","10"))))))))) -> 5
A20: 19 | B20: =estuary_data!U20*weights!$C$2 -> 0.050575582 | C20: =estuary_data!R20*weights!$C$5 -> 0.088405178 | D20: =estuary_data!V20*weights!$C$3 -> 0.031314087 | E20: =estuary_data!S20*weights!$C$6 -> 0.011207193 | F20: =estuary_data!W20*weights!$C$4 -> 0.097434637 | G20: =estuary_data!T20*weights!$C$7 -> 0.0465874 | H20: =SUM(B20:G20) -> 0.32552408 | I20: =IF(H20>$L$5/10*9,"1",IF(H20>$L$5/10*8,"2",IF(H20>$L$5/10*7,"3",IF(H20>$L$5/10*6,"4",IF(H20>$L$5/10*5,"5",IF(H20>$L$5/10*4,"6",IF(H20>$L$5/10*3,"7",IF(H20>$L$5/10*2,"8",IF(H20>$L$5/10,"9","10"))))))))) -> 6
A21: 20 | B21: =estuary_data!U21*weights!$C$2 -> 0.053943391 | C21: =estuary_data!R21*weights!$C$5 -> 0.089508732 | D21: =estuary_data!V21*weights!$C$3 -> 0.039597056 | E21: =estuary_data!S21*weights!$C$6 -> 0.014579366 | F21: =estuary_data!W21*weights!$C$4 -> 0.12564127 | G21: =estuary_data!T21*weights!$C$7 -> 0.048339253 | H21: =SUM(B21:G21) -> 0.37160907 | I21: =IF(H21>$L$5/10*9,"1",IF(H21>$L$5/10*8,"2",IF(H21>$L$5/10*7,"3",IF(H21>$L$5/10*6,"4",IF(H21>$L$5/10*5,"5",IF(H21>$L$5/10*4,"6",IF(H21>$L$5/10*3,"7",IF(H21>$L$5/10*2,"8",IF(H21>$L$5/10,"9","10"))))))))) -> 5
A22: 21 | B22: =estuary_data!U22*weights!$C$2 -> 0.054942168 | C22: =estuary_data!R22*weights!$C$5 -> 0.088998849 | D22: =estuary_data!V22*weights!$C$3 -> 0.040540422 | E22: =estuary_data!S22*weights!$C$6 -> 0.017306536 | F22: =estuary_data!W22*weights!$C$4 -> 0.13317485 | G22: =estuary_data!T22*weights!$C$7 -> 0.04324363 | H22: =SUM(B22:G22) -> 0.37820645 | I22: =IF(H22>$L$5/10*9,"1",IF(H22>$L$5/10*8,"2",IF(H22>$L$5/10*7,"3",IF(H22>$L$5/10*6,"4",IF(H22>$L$5/10*5,"5",IF(H22>$L$5/10*4,"6",IF(H22>$L$5/10*3,"7",IF(H22>$L$5/10*2,"8",IF(H22>$L$5/10,"9","10"))))))))) -> 5
A23: 22 | B23: =estuary_data!U23*weights!$C$2 -> 0.0430662 | C23: =estuary_data!R23*weights!$C$5 -> 0.079644913 | D23: =estuary_data!V23*weights!$C$3 -> 0.032548093 | E23: =estuary_data!S23*weights!$C$6 -> 0.013760544 | F23: =estuary_data!W23*weights!$C$4 -> 0.090213553 | G23: =estuary_data!T23*weights!$C$7 -> 0.012193588 | H23: =SUM(B23:G23) -> 0.27142689 | I23: =IF(H23>$L$5/10*9,"1",IF(H23>$L$5/10*8,"2",IF(H23>$L$5/10*7,"3",IF(H23>$L$5/10*6,"4",IF(H23>$L$5/10*5,"5",IF(H23>$L$5/10*4,"6",IF(H23>$L$5/10*3,"7",IF(H23>$L$5/10*2,"8",IF(H23>$L$5/10,"9","10"))))))))) -> 6
... A253: 252 | B253: =estuary_data!U253*weights!$C$2 -> 0.091876935 | C253: =estuary_data!R253*weights!$C$5 -> 0.11902146 | D253: =estuary_data!V253*weights!$C$3 -> 0.0091309237 | E253: =estuary_data!S253*weights!$C$6 -> 0.039219058 | F253: =estuary_data!W253*weights!$C$4 -> 0.011248789 | G253: =estuary_data!T253*weights!$C$7 -> 0.13831867 | H253: =SUM(B253:G253) -> 0.40881583 | I253: =IF(H253>$L$5/10*9,"1",IF(H253>$L$5/10*8,"2",IF(H253>$L$5/10*7,"3",IF(H253>$L$5/10*6,"4",IF(H253>$L$5/10*5,"5",IF(H253>$L$5/10*4,"6",IF(H253>$L$5/10*3,"7",IF(H253>$L$5/10*2,"8",IF(H253>$L$5/10,"9","10"))))))))) -> 4
A254: 253 | B254: =estuary_data!U748*weights!$C$2 -> 0.020697194 | C254: =estuary_data!R748*weights!$C$5 -> 0.091702036 | D254: =estuary_data!V748*weights!$C$3 -> 0.033265346 | E254: =estuary_data!S748*weights!$C$6 -> 0.048703011 | F254: =estuary_data!W748*weights!$C$4 -> 0.14435994 | G254: =estuary_data!T748*weights!$C$7 -> 0.069329836 | H254: =SUM(B254:G254) -> 0.40805737 | I254: =IF(H254>$L$5/10*9,"1",IF(H254>$L$5/10*8,"2",IF(H254>$L$5/10*7,"3",IF(H254>$L$5/10*6,"4",IF(H254>$L$5/10*5,"5",IF(H254>$L$5/10*4,"6",IF(H254>$L$5/10*3,"7",IF(H254>$L$5/10*2,"8",IF(H254>$L$5/10,"9","10"))))))))) -> 4
A255: 254 | B255: =estuary_data!U254*weights!$C$2 -> #VALUE! | C255: =estuary_data!R254*weights!$C$5 -> #VALUE! | D255: =estuary_data!V254*weights!$C$3 -> #VALUE! | E255: =estuary_data!S254*weights!$C$6 -> #VALUE! | F255: =estuary_data!W254*weights!$C$4 -> #VALUE! | G255: =estuary_data!T254*weights!$C$7 -> #VALUE! | H255: =SUM(B255:G255) -> #VALUE! | I255: =IF(H255>$L$5/10*9,"1",IF(H255>$L$5/10*8,"2",IF(H255>$L$5/10*7,"3",IF(H255>$L$5/10*6,"4",IF(H255>$L$5/10*5,"5",IF(H255>$L$5/10*4,"6",IF(H255>$L$5/10*3,"7",IF(H255>$L$5/10*2,"8",IF(H255>$L$5/10,"9","10"))))))))) -> #VALUE!
A256: 255 | B256: =estuary_data!U255*weights!$C$2 -> 0.099635487 | C256: =estuary_data!R255*weights!$C$5 -> 0.11633144 | D256: =estuary_data!V255*weights!$C$3 -> 0.011199683 | E256: =estuary_data!S255*weights!$C$6 -> 0.03411052 | F256: =estuary_data!W255*weights!$C$4 -> 0.020983142 | G256: =estuary_data!T255*weights!$C$7 -> 0.12693543 | H256: =SUM(B256:G256) -> 0.4091957 | I256: =IF(H256>$L$5/10*9,"1",IF(H256>$L$5/10*8,"2",IF(H256>$L$5/10*7,"3",IF(H256>$L$5/10*6,"4",IF(H256>$L$5/10*5,"5",IF(H256>$L$5/10*4,"6",IF(H256>$L$5/10*3,"7",IF(H256>$L$5/10*2,"8",IF(H256>$L$5/10,"9","10"))))))))) -> 4
A257: 256 | B257: =estuary_data!U256*weights!$C$2 -> 0.13495718 | C257: =estuary_data!R256*weights!$C$5 -> 0.11607241 | D257: =estuary_data!V256*weights!$C$3 -> 0.013404289 | E257: =estuary_data!S256*weights!$C$6 -> 0.031449359 | F257: =estuary_data!W256*weights!$C$4 -> 0.046072967 | G257: =estuary_data!T256*weights!$C$7 -> 0.12158169 | H257: =SUM(B257:G257) -> 0.46353789 | I257: =IF(H257>$L$5/10*9,"1",IF(H257>$L$5/10*8,"2",IF(H257>$L$5/10*7,"3",IF(H257>$L$5/10*6,"4",IF(H257>$L$5/10*5,"5",IF(H257>$L$5/10*4,"6",IF(H257>$L$5/10*3,"7",IF(H257>$L$5/10*2,"8",IF(H257>$L$5/10,"9","10"))))))))) -> 4
A258: 257 | B258: =estuary_data!U257*weights!$C$2 -> 0.10331244 | C258: =estuary_data!R257*weights!$C$5 -> 0.11590066 | D258: =estuary_data!V257*weights!$C$3 -> 0.014248943 | E258: =estuary_data!S257*weights!$C$6 -> 0.030811959 | F258: =estuary_data!W257*weights!$C$4 -> 0.040940661 | G258: =estuary_data!T257*weights!$C$7 -> 0.12000521 | H258: =SUM(B258:G258) -> 0.42521987 | I258: =IF(H258>$L$5/10*9,"1",IF(H258>$L$5/10*8,"2",IF(H258>$L$5/10*7,"3",IF(H258>$L$5/10*6,"4",IF(H258>$L$5/10*5,"5",IF(H258>$L$5/10*4,"6",IF(H258>$L$5/10*3,"7",IF(H258>$L$5/10*2,"8",IF(H258>$L$5/10,"9","10"))))))))) -> 4
A259: 258 | B259: =estuary_data!U258*weights!$C$2 -> 0.12606553 | C259: =estuary_data!R258*weights!$C$5 -> 0.11425486 | D259: =estuary_data!V258*weights!$C$3 -> 0.012357417 | E259: =estuary_data!S258*weights!$C$6 -> 0.03678282 | F259: =estuary_data!W258*weights!$C$4 -> 0.0320032 | G259: =estuary_data!T258*weights!$C$7 -> 0.13084528 | H259: =SUM(B259:G259) -> 0.45230911 | I259: =IF(H259>$L$5/10*9,"1",IF(H259>$L$5/10*8,"2",IF(H259>$L$5/10*7,"3",IF(H259>$L$5/10*6,"4",IF(H259>$L$5/10*5,"5",IF(H259>$L$5/10*4,"6",IF(H259>$L$5/10*3,"7",IF(H259>$L$5/10*2,"8",IF(H259>$L$5/10,"9","10"))))))))) -> 4
A260: 259 | B260: =estuary_data!U259*weights!$C$2 -> 0.093255874 | C260: =estuary_data!R259*weights!$C$5 -> 0.11412375 | D260: =estuary_data!V259*weights!$C$3 -> 0.011665581 | E260: =estuary_data!S259*weights!$C$6 -> 0.036125697 | F260: =estuary_data!W259*weights!$C$4 -> 0.020240282 | G260: =estuary_data!T259*weights!$C$7 -> 0.12948742 | H260: =SUM(B260:G260) -> 0.40489861 | I260: =IF(H260>$L$5/10*9,"1",IF(H260>$L$5/10*8,"2",IF(H260>$L$5/10*7,"3",IF(H260>$L$5/10*6,"4",IF(H260>$L$5/10*5,"5",IF(H260>$L$5/10*4,"6",IF(H260>$L$5/10*3,"7",IF(H260>$L$5/10*2,"8",IF(H260>$L$5/10,"9","10"))))))))) -> 4
A261: 260 | B261: =estuary_data!U260*weights!$C$2 -> 0.090010912 | C261: =estuary_data!R260*weights!$C$5 -> 0.12186487 | D261: =estuary_data!V260*weights!$C$3 -> 0.013590925 | E261: =estuary_data!S260*weights!$C$6 -> 0.012844542 | F261: =estuary_data!W260*weights!$C$4 -> 0.042140579 | G261: =estuary_data!T260*weights!$C$7 -> 0.091702972 | H261: =SUM(B261:G261) -> 0.3721548 | I261: =IF(H261>$L$5/10*9,"1",IF(H261>$L$5/10*8,"2",IF(H261>$L$5/10*7,"3",IF(H261>$L$5/10*6,"4",IF(H261>$L$5/10*5,"5",IF(H261>$L$5/10*4,"6",IF(H261>$L$5/10*3,"7",IF(H261>$L$5/10*2,"8",IF(H261>$L$5/10,"9","10"))))))))) -> 5
A262: 261 | B262: =estuary_data!U261*weights!$C$2 -> 0.10242163 | C262: =estuary_data!R261*weights!$C$5 -> 0.12110957 | D262: =estuary_data!V261*weights!$C$3 -> 0.013967998 | E262: =estuary_data!S261*weights!$C$6 -> 0.012851606 | F262: =estuary_data!W261*weights!$C$4 -> 0.0410881 | G262: =estuary_data!T261*weights!$C$7 -> 0.091494636 | H262: =SUM(B262:G262) -> 0.38293354 | I262: =IF(H262>$L$5/10*9,"1",IF(H262>$L$5/10*8,"2",IF(H262>$L$5/10*7,"3",IF(H262>$L$5/10*6,"4",IF(H262>$L$5/10*5,"5",IF(H262>$L$5/10*4,"6",IF(H262>$L$5/10*3,"7",IF(H262>$L$5/10*2,"8",IF(H262>$L$5/10,"9","10"))))))))) -> 5
A263: 262 | B263: =estuary_data!U262*weights!$C$2 -> 0.092795373 | C263: =estuary_data!R262*weights!$C$5 -> 0.12112264 | D263: =estuary_data!V262*weights!$C$3 -> 0.012690945 | E263: =estuary_data!S262*weights!$C$6 -> 0.012748534 | F263: =estuary_data!W262*weights!$C$4 -> 0.032906383 | G263: =estuary_data!T262*weights!$C$7 -> 0.090979318 | H263: =SUM(B263:G263) -> 0.36324319 | I263: =IF(H263>$L$5/10*9,"1",IF(H263>$L$5/10*8,"2",IF(H263>$L$5/10*7,"3",IF(H263>$L$5/10*6,"4",IF(H263>$L$5/10*5,"5",IF(H263>$L$5/10*4,"6",IF(H263>$L$5/10*3,"7",IF(H263>$L$5/10*2,"8",IF(H263>$L$5/10,"9","10"))))))))) -> 5
A264: 263 | B264: =estuary_data!U263*weights!$C$2 -> 0.092889127 | C264: =estuary_data!R263*weights!$C$5 -> 0.12044864 | D264: =estuary_data!V263*weights!$C$3 -> 0.011196533 | E264: =estuary_data!S263*weights!$C$6 -> 0.015322239 | F264: =estuary_data!W263*weights!$C$4 -> 0.026129213 | G264: =estuary_data!T263*weights!$C$7 -> 0.094768044 | H264: =SUM(B264:G264) -> 0.3607538 | I264: =IF(H264>$L$5/10*9,"1",IF(H264>$L$5/10*8,"2",IF(H264>$L$5/10*7,"3",IF(H264>$L$5/10*6,"4",IF(H264>$L$5/10*5,"5",IF(H264>$L$5/10*4,"6",IF(H264>$L$5/10*3,"7",IF(H264>$L$5/10*2,"8",IF(H264>$L$5/10,"9","10"))))))))) -> 5
A265: 264 | B265: =estuary_data!U264*weights!$C$2 -> 0.092280165 | C265: =estuary_data!R264*weights!$C$5 -> 0.12313768 | D265: =estuary_data!V264*weights!$C$3 -> 0.014644055 | E265: =estuary_data!S264*weights!$C$6 -> 0.0077337502 | F265: =estuary_data!W264*weights!$C$4 -> 0.038571146 | G265: =estuary_data!T264*weights!$C$7 -> 0.082524416 | H265: =SUM(B265:G265) -> 0.35889122 | I265: =IF(H265>$L$5/10*9,"1",IF(H265>$L$5/10*8,"2",IF(H265>$L$5/10*7,"3",IF(H265>$L$5/10*6,"4",IF(H265>$L$5/10*5,"5",IF(H265>$L$5/10*4,"6",IF(H265>$L$5/10*3,"7",IF(H265>$L$5/10*2,"8",IF(H265>$L$5/10,"9","10"))))))))) -> 5
A266: 265 | B266: =estuary_data!U265*weights!$C$2 -> 0.096211912 | C266: =estuary_data!R265*weights!$C$5 -> 0.12236175 | D266: =estuary_data!V265*weights!$C$3 -> 0.016903794 | E266: =estuary_data!S265*weights!$C$6 -> 0.0020422111 | F266: =estuary_data!W265*weights!$C$4 -> 0.062603361 | G266: =estuary_data!T265*weights!$C$7 -> 0.07236296 | H266: =SUM(B266:G266) -> 0.37248599 | I266: =IF(H266>$L$5/10*9,"1",IF(H266>$L$5/10*8,"2",IF(H266>$L$5/10*7,"3",IF(H266>$L$5/10*6,"4",IF(H266>$L$5/10*5,"5",IF(H266>$L$5/10*4,"6",IF(H266>$L$5/10*3,"7",IF(H266>$L$5/10*2,"8",IF(H266>$L$5/10,"9","10"))))))))) -> 5
... A367: 366 | B367: =estuary_data!U366*weights!$C$2 -> 0.07696809 | C367: =estuary_data!R366*weights!$C$5 -> 0.094569407 | D367: =estuary_data!V366*weights!$C$3 -> 0.021578982 | E367: =estuary_data!S366*weights!$C$6 -> 0.0065822999 | F367: =estuary_data!W366*weights!$C$4 -> 0.10157 | G367: =estuary_data!T366*weights!$C$7 -> 0.057078193 | H367: =SUM(B367:G367) -> 0.35834697 | I367: =IF(H367>$L$5/10*9,"1",IF(H367>$L$5/10*8,"2",IF(H367>$L$5/10*7,"3",IF(H367>$L$5/10*6,"4",IF(H367>$L$5/10*5,"5",IF(H367>$L$5/10*4,"6",IF(H367>$L$5/10*3,"7",IF(H367>$L$5/10*2,"8",IF(H367>$L$5/10,"9","10"))))))))) -> 5
A368: 367 | B368: =estuary_data!U749*weights!$C$2 -> 0.021715178 | C368: =estuary_data!R749*weights!$C$5 -> 0.091937961 | D368: =estuary_data!V749*weights!$C$3 -> 0.031778184 | E368: =estuary_data!S749*weights!$C$6 -> 0.047654447 | F368: =estuary_data!W749*weights!$C$4 -> 0.14384162 | G368: =estuary_data!T749*weights!$C$7 -> 0.067027732 | H368: =SUM(B368:G368) -> 0.40395512 | I368: =IF(H368>$L$5/10*9,"1",IF(H368>$L$5/10*8,"2",IF(H368>$L$5/10*7,"3",IF(H368>$L$5/10*6,"4",IF(H368>$L$5/10*5,"5",IF(H368>$L$5/10*4,"6",IF(H368>$L$5/10*3,"7",IF(H368>$L$5/10*2,"8",IF(H368>$L$5/10,"9","10"))))))))) -> 4
A369: 368 | B369: =estuary_data!U367*weights!$C$2 -> 0.084478793 | C369: =estuary_data!R367*weights!$C$5 -> 0.09134106 | D369: =estuary_data!V367*weights!$C$3 -> 0.047299716 | E369: =estuary_data!S367*weights!$C$6 -> 0.0053803067 | F369: =estuary_data!W367*weights!$C$4 -> 0.21928136 | G369: =estuary_data!T367*weights!$C$7 -> 0.053810432 | H369: =SUM(B369:G369) -> 0.50159167 | I369: =IF(H369>$L$5/10*9,"1",IF(H369>$L$5/10*8,"2",IF(H369>$L$5/10*7,"3",IF(H369>$L$5/10*6,"4",IF(H369>$L$5/10*5,"5",IF(H369>$L$5/10*4,"6",IF(H369>$L$5/10*3,"7",IF(H369>$L$5/10*2,"8",IF(H369>$L$5/10,"9","10"))))))))) -> 3
...

Sheet bird_scores
A1: EST_ID | B1: richness | C1: rel.abundance | D1: cumulative.score
A2: 2030 | B2: =estuary_data!Y643*weights!$C$9 -> 0.083438115 | C2: =estuary_data!X643*weights!$C$10 -> 0.90932 | D2: =SUM(B2:C2) -> 0.99275811 | E2: =IF(D2>$H$6/10*9,"1",IF(D2>$H$6/10*8,"2",IF(D2>$H$6/10*7,"3",IF(D2>$H$6/10*6,"4",IF(D2>$H$6/10*5,"5",IF(D2>$H$6/10*4,"6",IF(D2>$H$6/10*3,"7",IF(D2>$H$6/10*2,"8",IF(D2>$H$6/10,"9","10"))))))))) -> 1
A3: 19 | B3: =estuary_data!Y20*weights!$C$9 -> 0.020689735 | C3: =estuary_data!X20*weights!$C$10 -> 0.077385751 | D3: =SUM(B3:C3) -> 0.098075485 | E3: =IF(D3>$H$6/10*9,"1",IF(D3>$H$6/10*8,"2",IF(D3>$H$6/10*7,"3",IF(D3>$H$6/10*6,"4",IF(D3>$H$6/10*5,"5",IF(D3>$H$6/10*4,"6",IF(D3>$H$6/10*3,"7",IF(D3>$H$6/10*2,"8",IF(D3>$H$6/10,"9","10"))))))))) -> 10
A4: 20 | B4: =estuary_data!Y21*weights!$C$9 -> 0.01514704 | C4: =estuary_data!X21*weights!$C$10 -> 0.075141088 | D4: =SUM(B4:C4) -> 0.090288128 | E4: =IF(D4>$H$6/10*9,"1",IF(D4>$H$6/10*8,"2",IF(D4>$H$6/10*7,"3",IF(D4>$H$6/10*6,"4",IF(D4>$H$6/10*5,"5",IF(D4>$H$6/10*4,"6",IF(D4>$H$6/10*3,"7",IF(D4>$H$6/10*2,"8",IF(D4>$H$6/10,"9","10"))))))))) -> 10
A5: 27 | B5: =estuary_data!Y28*weights!$C$9 -> 0.018622965 | C5: =estuary_data!X28*weights!$C$10 -> 0.080371243 | D5: =SUM(B5:C5) -> 0.098994208 | E5: =IF(D5>$H$6/10*9,"1",IF(D5>$H$6/10*8,"2",IF(D5>$H$6/10*7,"3",IF(D5>$H$6/10*6,"4",IF(D5>$H$6/10*5,"5",IF(D5>$H$6/10*4,"6",IF(D5>$H$6/10*3,"7",IF(D5>$H$6/10*2,"8",IF(D5>$H$6/10,"9","10"))))))))) -> 10
A6: 38 | B6: =estuary_data!Y39*weights!$C$9 -> 0.017498753 | C6: =estuary_data!X39*weights!$C$10 -> 0.07576195 | D6: =SUM(B6:C6) -> 0.093260703 | E6: =IF(D6>$H$6/10*9,"1",IF(D6>$H$6/10*8,"2",IF(D6>$H$6/10*7,"3",IF(D6>$H$6/10*6,"4",IF(D6>$H$6/10*5,"5",IF(D6>$H$6/10*4,"6",IF(D6>$H$6/10*3,"7",IF(D6>$H$6/10*2,"8",IF(D6>$H$6/10,"9","10"))))))))) -> 10 | G6: max | H6: 0.9927
A7: 40 | B7: =estuary_data!Y41*weights!$C$9 -> 0.020206795 | C7: =estuary_data!X41*weights!$C$10 -> 0.079055342 | D7: =SUM(B7:C7) -> 0.099262137 | E7: =IF(D7>$H$6/10*9,"1",IF(D7>$H$6/10*8,"2",IF(D7>$H$6/10*7,"3",IF(D7>$H$6/10*6,"4",IF(D7>$H$6/10*5,"5",IF(D7>$H$6/10*4,"6",IF(D7>$H$6/10*3,"7",IF(D7>$H$6/10*2,"8",IF(D7>$H$6/10,"9","10"))))))))) -> 10
A8: 41 | B8: =estuary_data!Y42*weights!$C$9 -> 0.020004549 | C8: =estuary_data!X42*weights!$C$10 -> 0.076968189 | D8: =SUM(B8:C8) -> 0.096972738 | E8: =IF(D8>$H$6/10*9,"1",IF(D8>$H$6/10*8,"2",IF(D8>$H$6/10*7,"3",IF(D8>$H$6/10*6,"4",IF(D8>$H$6/10*5,"5",IF(D8>$H$6/10*4,"6",IF(D8>$H$6/10*3,"7",IF(D8>$H$6/10*2,"8",IF(D8>$H$6/10,"9","10"))))))))) -> 10
A9: 47 | B9: =estuary_data!Y48*weights!$C$9 -> 0.025359019 | C9: =estuary_data!X48*weights!$C$10 -> 0.067556647 | D9: =SUM(B9:C9) -> 0.092915666 | E9: =IF(D9>$H$6/10*9,"1",IF(D9>$H$6/10*8,"2",IF(D9>$H$6/10*7,"3",IF(D9>$H$6/10*6,"4",IF(D9>$H$6/10*5,"5",IF(D9>$H$6/10*4,"6",IF(D9>$H$6/10*3,"7",IF(D9>$H$6/10*2,"8",IF(D9>$H$6/10,"9","10"))))))))) -> 10
A10: 55 | B10: =estuary_data!Y56*weights!$C$9 -> 0.02118222 | C10: =estuary_data!X56*weights!$C$10 -> 0.058355859 | D10: =SUM(B10:C10) -> 0.079538079 | E10: =IF(D10>$H$6/10*9,"1",IF(D10>$H$6/10*8,"2",IF(D10>$H$6/10*7,"3",IF(D10>$H$6/10*6,"4",IF(D10>$H$6/10*5,"5",IF(D10>$H$6/10*4,"6",IF(D10>$H$6/10*3,"7",IF(D10>$H$6/10*2,"8",IF(D10>$H$6/10,"9","10"))))))))) -> 10 | G10: ranked high to low
A11: 66 | B11: =estuary_data!Y67*weights!$C$9 -> 0.016890846 | C11: =estuary_data!X67*weights!$C$10 -> 0.056134938 | D11: =SUM(B11:C11) -> 0.073025784 | E11: =IF(D11>$H$6/10*9,"1",IF(D11>$H$6/10*8,"2",IF(D11>$H$6/10*7,"3",IF(D11>$H$6/10*6,"4",IF(D11>$H$6/10*5,"5",IF(D11>$H$6/10*4,"6",IF(D11>$H$6/10*3,"7",IF(D11>$H$6/10*2,"8",IF(D11>$H$6/10,"9","10"))))))))) -> 10
A12: 67 | B12: =estuary_data!Y68*weights!$C$9 -> 0.013001513 | C12: =estuary_data!X68*weights!$C$10 -> 0.062549545 | D12: =SUM(B12:C12) -> 0.075551058 | E12: =IF(D12>$H$6/10*9,"1",IF(D12>$H$6/10*8,"2",IF(D12>$H$6/10*7,"3",IF(D12>$H$6/10*6,"4",IF(D12>$H$6/10*5,"5",IF(D12>$H$6/10*4,"6",IF(D12>$H$6/10*3,"7",IF(D12>$H$6/10*2,"8",IF(D12>$H$6/10,"9","10"))))))))) -> 10
A13: 68 | B13: =estuary_data!Y69*weights!$C$9 -> 0.018265471 | C13: =estuary_data!X69*weights!$C$10 -> 0.078844251 | D13: =SUM(B13:C13) -> 0.097109723 | E13: =IF(D13>$H$6/10*9,"1",IF(D13>$H$6/10*8,"2",IF(D13>$H$6/10*7,"3",IF(D13>$H$6/10*6,"4",IF(D13>$H$6/10*5,"5",IF(D13>$H$6/10*4,"6",IF(D13>$H$6/10*3,"7",IF(D13>$H$6/10*2,"8",IF(D13>$H$6/10,"9","10"))))))))) -> 10
A14: 69 | B14: =estuary_data!Y70*weights!$C$9 -> 0.013954704 | C14: =estuary_data!X70*weights!$C$10 -> 0.068595764 | D14: =SUM(B14:C14) -> 0.082550468 | E14: =IF(D14>$H$6/10*9,"1",IF(D14>$H$6/10*8,"2",IF(D14>$H$6/10*7,"3",IF(D14>$H$6/10*6,"4",IF(D14>$H$6/10*5,"5",IF(D14>$H$6/10*4,"6",IF(D14>$H$6/10*3,"7",IF(D14>$H$6/10*2,"8",IF(D14>$H$6/10,"9","10"))))))))) -> 10
A15: 70 | B15: =estuary_data!Y71*weights!$C$9 -> 0.018991942 | C15: =estuary_data!X71*weights!$C$10 -> 0.073288132 | D15: =SUM(B15:C15) -> 0.092280074 | E15: =IF(D15>$H$6/10*9,"1",IF(D15>$H$6/10*8,"2",IF(D15>$H$6/10*7,"3",IF(D15>$H$6/10*6,"4",IF(D15>$H$6/10*5,"5",IF(D15>$H$6/10*4,"6",IF(D15>$H$6/10*3,"7",IF(D15>$H$6/10*2,"8",IF(D15>$H$6/10,"9","10"))))))))) -> 10
A16: 77 | B16: =estuary_data!Y78*weights!$C$9 -> 0.023100087 | C16: =estuary_data!X78*weights!$C$10 -> 0.072180986 | D16: =SUM(B16:C16) -> 0.095281073 | E16: =IF(D16>$H$6/10*9,"1",IF(D16>$H$6/10*8,"2",IF(D16>$H$6/10*7,"3",IF(D16>$H$6/10*6,"4",IF(D16>$H$6/10*5,"5",IF(D16>$H$6/10*4,"6",IF(D16>$H$6/10*3,"7",IF(D16>$H$6/10*2,"8",IF(D16>$H$6/10,"9","10"))))))))) -> 10
A17: 86 | B17: =estuary_data!Y87*weights!$C$9 -> 0.020138982 | C17: =estuary_data!X87*weights!$C$10 -> 0.063897292 | D17: =SUM(B17:C17) -> 0.084036274 | E17: =IF(D17>$H$6/10*9,"1",IF(D17>$H$6/10*8,"2",IF(D17>$H$6/10*7,"3",IF(D17>$H$6/10*6,"4",IF(D17>$H$6/10*5,"5",IF(D17>$H$6/10*4,"6",IF(D17>$H$6/10*3,"7",IF(D17>$H$6/10*2,"8",IF(D17>$H$6/10,"9","10"))))))))) -> 10
A18: 89 | B18: =estuary_data!Y90*weights!$C$9 -> 0.020539757 | C18: =estuary_data!X90*weights!$C$10 -> 0.072170601 | D18: =SUM(B18:C18) -> 0.092710358 | E18: =IF(D18>$H$6/10*9,"1",IF(D18>$H$6/10*8,"2",IF(D18>$H$6/10*7,"3",IF(D18>$H$6/10*6,"4",IF(D18>$H$6/10*5,"5",IF(D18>$H$6/10*4,"6",IF(D18>$H$6/10*3,"7",IF(D18>$H$6/10*2,"8",IF(D18>$H$6/10,"9","10"))))))))) -> 10
A19: 95 | B19: =estuary_data!Y96*weights!$C$9 -> 0.017470464 | C19: =estuary_data!X96*weights!$C$10 -> 0.077697037 | D19: =SUM(B19:C19) -> 0.095167501 | E19: =IF(D19>$H$6/10*9,"1",IF(D19>$H$6/10*8,"2",IF(D19>$H$6/10*7,"3",IF(D19>$H$6/10*6,"4",IF(D19>$H$6/10*5,"5",IF(D19>$H$6/10*4,"6",IF(D19>$H$6/10*3,"7",IF(D19>$H$6/10*2,"8",IF(D19>$H$6/10,"9","10"))))))))) -> 10
A20: 99 | B20: =estuary_data!Y100*weights!$C$9 -> 0.0096975266 | C20: =estuary_data!X100*weights!$C$10 -> 0.055988556 | D20: =SUM(B20:C20) -> 0.065686082 | E20: =IF(D20>$H$6/10*9,"1",IF(D20>$H$6/10*8,"2",IF(D20>$H$6/10*7,"3",IF(D20>$H$6/10*6,"4",IF(D20>$H$6/10*5,"5",IF(D20>$H$6/10*4,"6",IF(D20>$H$6/10*3,"7",IF(D20>$H$6/10*2,"8",IF(D20>$H$6/10,"9","10"))))))))) -> 10
A21: 105 | B21: =estuary_data!Y106*weights!$C$9 -> 0.0217467 | C21: =estuary_data!X106*weights!$C$10 -> 0.057792238 | D21: =SUM(B21:C21) -> 0.079538938 | E21: =IF(D21>$H$6/10*9,"1",IF(D21>$H$6/10*8,"2",IF(D21>$H$6/10*7,"3",IF(D21>$H$6/10*6,"4",IF(D21>$H$6/10*5,"5",IF(D21>$H$6/10*4,"6",IF(D21>$H$6/10*3,"7",IF(D21>$H$6/10*2,"8",IF(D21>$H$6/10,"9","10"))))))))) -> 10
A22: 110 | B22: =estuary_data!Y111*weights!$C$9 -> 0.017558997 | C22: =estuary_data!X111*weights!$C$10 -> 0.073958816 | D22: =SUM(B22:C22) -> 0.091517813 | E22: =IF(D22>$H$6/10*9,"1",IF(D22>$H$6/10*8,"2",IF(D22>$H$6/10*7,"3",IF(D22>$H$6/10*6,"4",IF(D22>$H$6/10*5,"5",IF(D22>$H$6/10*4,"6",IF(D22>$H$6/10*3,"7",IF(D22>$H$6/10*2,"8",IF(D22>$H$6/10,"9","10"))))))))) -> 10
A23: 115 | B23: =estuary_data!Y116*weights!$C$9 -> 0.0224073 | C23: =estuary_data!X116*weights!$C$10 -> 0.07143208 | D23: =SUM(B23:C23) -> 0.093839381 | E23: =IF(D23>$H$6/10*9,"1",IF(D23>$H$6/10*8,"2",IF(D23>$H$6/10*7,"3",IF(D23>$H$6/10*6,"4",IF(D23>$H$6/10*5,"5",IF(D23>$H$6/10*4,"6",IF(D23>$H$6/10*3,"7",IF(D23>$H$6/10*2,"8",IF(D23>$H$6/10,"9","10"))))))))) -> 10
A24: 117 | B24: =estuary_data!Y118*weights!$C$9 -> 0.02025639 | C24: =estuary_data!X118*weights!$C$10 -> 0.072601841 | D24: =SUM(B24:C24) -> 0.09285823 | E24: =IF(D24>$H$6/10*9,"1",IF(D24>$H$6/10*8,"2",IF(D24>$H$6/10*7,"3",IF(D24>$H$6/10*6,"4",IF(D24>$H$6/10*5,"5",IF(D24>$H$6/10*4,"6",IF(D24>$H$6/10*3,"7",IF(D24>$H$6/10*2,"8",IF(D24>$H$6/10,"9","10"))))))))) -> 10
A25: 118 | B25: =estuary_data!Y119*weights!$C$9 -> 0.01925616 | C25: =estuary_data!X119*weights!$C$10 -> 0.069060149 | D25: =SUM(B25:C25) -> 0.088316308 | E25: =IF(D25>$H$6/10*9,"1",IF(D25>$H$6/10*8,"2",IF(D25>$H$6/10*7,"3",IF(D25>$H$6/10*6,"4",IF(D25>$H$6/10*5,"5",IF(D25>$H$6/10*4,"6",IF(D25>$H$6/10*3,"7",IF(D25>$H$6/10*2,"8",IF(D25>$H$6/10,"9","10"))))))))) -> 10
A26: 120 | B26: =estuary_data!Y121*weights!$C$9 -> 0.015012761 | C26: =estuary_data!X121*weights!$C$10 -> 0.057062738 | D26: =SUM(B26:C26) -> 0.072075499 | E26: =IF(D26>$H$6/10*9,"1",IF(D26>$H$6/10*8,"2",IF(D26>$H$6/10*7,"3",IF(D26>$H$6/10*6,"4",IF(D26>$H$6/10*5,"5",IF(D26>$H$6/10*4,"6",IF(D26>$H$6/10*3,"7",IF(D26>$H$6/10*2,"8",IF(D26>$H$6/10,"9","10"))))))))) -> 10
A27: 126 | B27: =estuary_data!Y127*weights!$C$9 -> 0.016851547 | C27: =estuary_data!X127*weights!$C$10 -> 0.067472597 | D27: =SUM(B27:C27) -> 0.084324144 | E27: =IF(D27>$H$6/10*9,"1",IF(D27>$H$6/10*8,"2",IF(D27>$H$6/10*7,"3",IF(D27>$H$6/10*6,"4",IF(D27>$H$6/10*5,"5",IF(D27>$H$6/10*4,"6",IF(D27>$H$6/10*3,"7",IF(D27>$H$6/10*2,"8",IF(D27>$H$6/10,"9","10"))))))))) -> 10
A28: 149 | B28: =estuary_data!Y150*weights!$C$9 -> 0.021136531 | C28: =estuary_data!X150*weights!$C$10 -> 0.047109736 | D28: =SUM(B28:C28) -> 0.068246267 | E28: =IF(D28>$H$6/10*9,"1",IF(D28>$H$6/10*8,"2",IF(D28>$H$6/10*7,"3",IF(D28>$H$6/10*6,"4",IF(D28>$H$6/10*5,"5",IF(D28>$H$6/10*4,"6",IF(D28>$H$6/10*3,"7",IF(D28>$H$6/10*2,"8",IF(D28>$H$6/10,"9","10"))))))))) -> 10
